<mujoco model="ac2">
  <compiler angle="radian" autolimits="true"/>

  <option cone="elliptic" impratio="100"/>  

  <default>
    <default class="ac2">
      <geom friction="0.0" margin="0.001"/>
      <joint axis="0 1 0"  damping="0.0" armature="0.0" frictionloss="0.0"/>
    </default>

    <default class="hip_joint">
      <geom friction="0.0" margin="0.001"/>
      <joint axis="0 1 0"  damping="0.0" armature="0.0" frictionloss="0.0"/>
    </default>

    <default class="thigh_joint">
      <geom friction="0.0" margin="0.001"/>
      <joint axis="0 1 0"  damping="0.0" armature="0.0" frictionloss="0.0"/>
    </default>

    <default class="calf_joint">
      <geom friction="0.0" margin="0.001"/>
      <joint axis="0 1 0"  damping="0.0" armature="0.06" frictionloss="0.0"/>
    </default>

    <default class="visual">
        <geom type="mesh" contype="0" conaffinity="0" group="2" material="dark"/>
    </default>

    <default class="collision">
      <geom  group="3" type="capsule" condim='3' contype="1" conaffinity="15" solref='0.001 2' friction='1 1'/>
      <default class="base">
        <geom size="0.18 0.1 0.08" pos="0 0 0.033" type="box" rgba="0.79216 0.81961 0.93333 1"/>
      </default>
      <default class="mid360">
        <geom type="sphere" size="0.023" pos="0.288317 0 0.0950137" rgba="1 1 1 1"/>
      </default>
      <default class="thigh">
        <geom size="0.03 0.03 0.13" pos="-0.014352 0 -0.086111" type="box" rgba="0.79216 0.81961 0.93333 1"/>
      </default>
      <default class="calf">
        <geom size="0.01 0.01 0.15" pos="0 0 -0.1" type="box" rgba="0.79216 0.81961 0.93333 1"/>
      </default>
      <default class="foot">
        <geom type="sphere" size="0.026" pos="0 0 -0.26" 
          friction="0.0 0.0 0.0"/>
      </default>
    </default>

  </default>

  <asset>
    <material name="dark" specular="0" shininess="0.25" rgba="0.2 0.2 0.2 1"/>
    <mesh file="../meshes/base.STL"/>

    <mesh file="../meshes/fl_hip.STL"/>
    <mesh file="../meshes/fr_hip.STL"/>
    <mesh file="../meshes/rl_hip.STL"/>
    <mesh file="../meshes/rr_hip.STL"/>

    <mesh file="../meshes/fl_thigh.STL"/>
    <mesh file="../meshes/fr_thigh.STL"/>
    <mesh file="../meshes/rl_thigh.STL"/>
    <mesh file="../meshes/rr_thigh.STL"/>

    <mesh file="../meshes/fl_calf.STL"/>
    <mesh file="../meshes/fr_calf.STL"/>
    <mesh file="../meshes/rl_calf.STL"/>
    <mesh file="../meshes/rr_calf.STL"/>
  </asset>

  <worldbody>
    <light name="spotlight" mode="targetbodycom" target="base" pos="0 -1 2"/>
    <body name="base" pos="0 0 0.42">
      <inertial pos="0.019195 0 0.012831" quat="0.00114202 0.67686 0.000948387 0.736111" mass="9.83" diaginertia="0.22729 0.204936 0.0572096"/>
      <joint name="free" type="free" limited="false" actuatorfrclimited="false"/>
      <site name='imu' size='0.01' pos='0.0 0 0.0'/>
      <geom class="visual" mesh="base"/>
      <geom class="base"/>
      <geom class="mid360"/>

      <body name="FL_hip" pos="0.24 0.062 0">
        <inertial pos="-0.003719 0.024390 0.002636" mass="1.25"
          fullinertia="0.001250756 0.001692423 0.001362387 -0.0000112145 -0.0000013266 0.0000035135"/>
        <joint class="hip_joint" name="FL_hip_joint" pos="0 0 0" axis="1 0 0" range="-0.802851 0.802851" actuatorfrcrange="-50.5 50.5"/>
        <geom class="visual" mesh="fl_hip"/>
        <body name="FL_thigh" pos="0 0.095 0">
          <inertial pos="-0.012327 -0.005701 -0.067505" mass="1.38"
            fullinertia="0.006818525 0.006975306 0.001150878 0.0000058813 -0.0000719904 0.000022201"/>
          <joint class="thigh_joint" name="FL_thigh_joint" pos="0 0 0" axis="0 1 0" range="-1.0472 4.18879" actuatorfrcrange="-60.5 60.5"/>
          <geom class="visual" mesh="fl_thigh"/>
          <geom class="thigh"/>
          <body name="FL_calf" pos="0 0 -0.246">
            <inertial pos="0.00926422 -0.00100043 -0.0737639" quat="0.707037 0.0115305 0.0115347 0.706988" mass="0.281" diaginertia="0.00379332 0.00376662 6.55418e-05"/>
            <joint class="calf_joint" name="FL_calf_joint" pos="0 0 0" axis="0 1 0" range="-2.69653 -0.916298" actuatorfrcrange="-70.5 70.5"/>
            <geom class="visual" mesh="fl_calf"/>
            <geom class="calf"/>
            <geom class="foot" name="FL_foot_fixed"/>
          </body>
        </body>
      </body>

      <body name="FR_hip" pos="0.24 -0.062 0">
        <inertial pos="-0.003719 -0.024390 0.002636" mass="1.25"
          fullinertia="0.001250756 0.001692423 0.001362387 0.0000112145 -0.0000013266 -0.0000035135"/>
        <joint class="hip_joint" name="FR_hip_joint" pos="0 0 0" axis="1 0 0" range="-0.802851 0.802851" actuatorfrcrange="-50.5 50.5"/>
        <geom class="visual" mesh="fr_hip"/>
        <body name="FR_thigh" pos="0 -0.095 0">
          <inertial pos="-0.012327 0.005701 -0.067505" mass="1.38"
            fullinertia="0.006818525 0.006975306 0.001150878 -0.0000058813 -0.0000719904 -0.000022201"/>
          <joint class="thigh_joint" name="FR_thigh_joint" pos="0 0 0" axis="0 1 0" range="-1.0472 4.18879" actuatorfrcrange="-60.5 60.5"/>
          <geom class="visual" mesh="fr_thigh"/>
          <geom class="thigh"/>
          <body name="FR_calf" pos="0 0.001 -0.246">
            <inertial pos="0.00926422 -0.00100043 -0.0737639" quat="0.707037 0.0115305 0.0115347 0.706988" mass="0.281" diaginertia="0.00379332 0.00376662 6.55418e-05"/>
            <joint class="calf_joint" name="FR_calf_joint" pos="0 0 0" axis="0 1 0" range="-2.69653 -0.916298" actuatorfrcrange="-70.5 70.5"/>
            <geom class="visual" mesh="fr_calf"/>
            <geom class="calf"/>
            <geom class="foot" name="FR_foot_fixed"/>
          </body>
        </body>
      </body>

      <body name="RL_hip" pos="-0.24 0.062 0">
        <inertial mass="1.25" pos="0.003719 0.024390 0.002636"
          fullinertia="0.001250756 0.001692423 0.001362387 0.0000112145 0.0000013266 0.0000035135"/>
        <joint class="hip_joint" name="RL_hip_joint" pos="0 0 0" axis="1 0 0" range="-0.802851 0.802851" actuatorfrcrange="-50.5 50.5"/>
        <geom class="visual" mesh="rl_hip"/>
        <body name="RL_thigh" pos="0 0.095 0">
          <inertial pos="-0.012327 -0.005701 -0.067505" mass="1.38"
            fullinertia="0.006818525 0.006975306 0.001150878 0.0000058813 -0.0000719904 0.000022201"/>
          <joint class="thigh_joint" name="RL_thigh_joint" pos="0 0 0" axis="0 1 0" range="-1.0472 4.18879" actuatorfrcrange="-60.5 60.5"/>
          <geom class="visual" mesh="rl_thigh"/>
          <geom class="thigh"/>
          <body name="RL_calf" pos="0 0 -0.246">
            <inertial pos="0.00926422 -0.00100043 -0.0737639" quat="0.707037 0.0115305 0.0115347 0.706988" mass="0.281" diaginertia="0.00379332 0.00376662 6.55418e-05"/>
            <joint class="calf_joint" name="RL_calf_joint" pos="0 0 0" axis="0 1 0" range="-2.69653 -0.916298" actuatorfrcrange="-70.5 70.5"/>
            <geom class="visual" mesh="rl_calf"/>
            <geom class="calf"/>
            <geom class="foot" name="RL_foot_fixed"/>
          </body>
        </body>
      </body>

      <body name="RR_hip" pos="-0.24 -0.062 0">
        <inertial pos="0.003719 -0.024390 0.002636" mass="1.25"
          fullinertia="0.001250756 0.001692423 0.001362387 -0.0000112145 0.0000013266 -0.0000035135"/>
        <joint class="hip_joint" name="RR_hip_joint" pos="0 0 0" axis="1 0 0" range="-0.802851 0.802851" actuatorfrcrange="-50.5 50.5"/>
        <geom class="visual" mesh="rr_hip"/>
        <body name="RR_thigh" pos="0 -0.095 0">
          <inertial pos="-0.012327 0.005701 -0.067505" mass="1.38"
            fullinertia="0.006818525 0.006975306 0.001150878 -0.0000058813 -0.0000719904 -0.000022201"/>
          <joint class="thigh_joint" name="RR_thigh_joint" pos="0 0 0" axis="0 1 0" range="-1.0472 4.18879" actuatorfrcrange="-60.5 60.5"/>
          <geom class="visual" mesh="rr_thigh"/>
          <geom class="thigh"/>
          <body name="RR_calf" pos="0 0.001 -0.246">
            <inertial pos="0.00926422 -0.00100043 -0.0737639" quat="0.707037 0.0115305 0.0115347 0.706988" mass="0.281" diaginertia="0.00379332 0.00376662 6.55418e-05"/>
            <joint class="calf_joint" name="RR_calf_joint" pos="0 0 0" axis="0 1 0" range="-2.69653 -0.916298" actuatorfrcrange="-70.5 70.5"/>
            <geom class="visual" mesh="rr_calf"/>
            <geom class="calf"/>
            <geom class="foot" name="RR_foot_fixed"/>
          </body>
        </body>
      </body>
    </body>
  </worldbody>

  <actuator>
    <motor name="FL_hip_joint" joint="FL_hip_joint" gear="1"/>
    <motor name="FL_thigh_joint" joint="FL_thigh_joint" gear="1"/>
    <motor name="FL_calf_joint" joint="FL_calf_joint" gear="1"/>

    <motor name="FR_hip_joint" joint="FR_hip_joint" gear="1"/>
    <motor name="FR_thigh_joint" joint="FR_thigh_joint" gear="1"/>
    <motor name="FR_calf_joint" joint="FR_calf_joint" gear="1"/>

    <motor name="RL_hip_joint"  joint="RL_hip_joint" gear="1"/>
    <motor name="RL_thigh_joint" joint="RL_thigh_joint" gear="1"/>
    <motor name="RL_calf_joint" joint="RL_calf_joint" gear="1"/>

    <motor name="RR_hip_joint" joint="RR_hip_joint" gear="1"/>
    <motor name="RR_thigh_joint" joint="RR_thigh_joint" gear="1"/>
    <motor name="RR_calf_joint" joint="RR_calf_joint" gear="1"/>

  </actuator>

  <sensor>
    <framequat     name='orientation' objtype='site' noise='0.001' objname='imu'/>
    <gyro          name='angular-velocity'    site='imu' noise='0.005' cutoff='34.9'/>
    <accelerometer name='linear-acceleration' site='imu' noise='0.005' cutoff='157'/>
  </sensor>

  <keyframe>
    <key name="default_pos" 
          qpos="0 0 0.39 
                1 0 0 0 
                -0.1 1.0 -1.55 
                0.1 1.0 -1.55 
                -0.1 0.8 -1.55 
                0.1 0.8 -1.55"
          ctrl="0 0.0 0.0 
                0 0.0 0.0 
                0 0.0 0.0 
                0 0.0 0.0"/>
    <key name="home_a1" 
          qpos="0 0 0.27 
                1 0 0 0 
                0.455 1.069 -2.64 
                -0.455 1.069 -2.64 
                0.455 1.069 -2.64 
                -0.455 1.069 -2.64"
          ctrl="0.0 0.0 0.0 
                0.0 0.0 0.0 
                0.0 0.0 0.0 
                0.0 0.0 0.0"/>
  </keyframe>

</mujoco>
